Workbook

Sheet Main Pricing
B1: Shocks - F | C1: Shocks - R | D1: BP - F | E1: BP - R | F1: B-Sensors-F | G1: B-Sensors-R | H1: Disc - F | I1: Disc - R | J1: BJ - U / BJ - L | L1: Upper Arm C | M1: Lower Arm | N1: Ball Ends | O1: TRE | P1: LA-C | Q1: DRIVE SHAFT | R1: LABB | S1: LABS | T1: SL - F | U1: SL - R | V1: SB | W1: HOBB - F | X1: HOBB - R | Y1: HOBC - R | Z1: T-Mount | AA1: PS Pump | AB1: PS Motor | AC1: Water P | AD1: Water Jacket | AE1: EO | AF1: OF | AG1: AF | AH1: A/C F | AI1: SP | AJ1: Radiator | AK1: FF | AL1: Coil | AM1: Horn Coil | AN1: INJECTORS | AO1: BOOTH SHOCKS | AP1: Timing B | AQ1: Belt Adjuster | AR1: Fan B | AS1: TURBO CHARGER | AT1: Thermostat | AU1: Cam Shaft S | AV1: Crank Shaft Pos S | AW1: Alternator | AX1: Speed Sensor | AY1: Head G | AZ1: OverH G | BA1: Crank Shaft Bea | BB1: Eng Bearing | BC1: Rings | BD1: Oil Pump | BE1: Fuel Pump | BF1: Central Lock Motor | BG1: Steering Angle Sensor | BH1: Mass Sensor | BI1: Map Sensor | BJ1: Knock Sensor | BK1: Air Flow Sensor | BL1: Engine Seat - Top | BM1: Engine Seat - Down | BN1: Gearbox Seat | BO1: Clutch System | BP1: Steering Rack | BQ1: Water Tank | BR1: Servo | BS1: Door Switch | BT1: Water Thermostat | BU1: FUEL PUMP REP. KITS | BV1: Exhaust | BW1: Wiper Motor | BX1: Adjuster | BY1: Windscreen | BZ1: AC Condensor | CA1: Air Lifting Motor | CC1: Head Gasket | CE1: Arm Bushing - R | CG1: Oxygen Sensor | CI1: Steering Rack | CK1: Abs Sensor | CM1: Belt Roller | CO1: Tension Bar | CQ1: Spring Coil | CR1: BELT SIZE | CS1: CVT VALVE
A2: TOYOTA | AX2: 350
A3: Corolla | B3: 2850 | C3: 1820 | D3: 780 | E3: 580 | H3: 200 | J3: 980 | O3: 480 | P3: 2850 | Q3: 3200 | R3: 560 | S3: 300 | T3: 520 | U3: 200 | V3: 200 | W3: 800 | X3: 780 | Y3: 1360 | AC3: =442.56+13.28 -> 455.84 | AD3: 800 | AE3: 600 | AF3: 140 | AG3: 220 | AI3: 450 | AJ3: 850 | AL3: 350 | AR3: 180 | AT3: 1800 | AW3: 480 | AX3: 350 | AY3: =218.88+6.57 -> 225.45 | BK3: 480 | BL3: 950 | BM3: 850 | BN3: 650 | BP3: 3200 | BQ3: 960 | BV3: 600 | BW3: 1460 | BY3: 1480 | CC3: 260 | CI3: 2800 | CK3: 350
A4: Yaris | B4: 1750 | C4: 1450 | D4: 380 | E4: 340 | J4: 450 | O4: 480 | P4: 2850 | R4: 280 | S4: 200 | T4: 350 | U4: 200 | V4: 150 | W4: 480 | Y4: 1360 | AC4: =442.56+13.28 -> 455.84 | AE4: 400 | AF4: 70 | AG4: 110 | AI4: 350 | AL4: 420 | AR4: 225 | AV4: 560 | AY4: =218.88+6.57 -> 225.45 | BL4: 600 | BM4: 250 | BN4: 150 | BQ4: 845
A5: Camry | B5: 2350 | C5: 1820 | D5: 780 | E5: 580 | J5: 980 | O5: 480 | Q5: 750 | R5: 320 | S5: 250 | T5: 580 | U5: 320 | V5: 200 | W5: 680 | Y5: 1120 | Z5: 500 | AC5: 960 | AE5: 600 | AF5: 140 | AG5: 220 | AH5: 180 | AI5: 350 | AM5: 780 | AR5: 330 | AX5: 450 | AY5: 225.45 | BE5: 460 | BH5: 550 | BJ5: 370 | BL5: 600 | BM5: 250 | BP5: 2600 | BS5: 450 | BT5: 450 | CK5: 350 | CR5: 6PK 1275
A6: Avensis | B6: 1820 | C6: 1480 | D6: 780 | E6: 580 | AE6: 600 | AF6: 140 | AG6: 220 | AH6: 180 | AI6: 350 | AL6: 350 | BL6: 600 | BN6: 380
A7: Venza | B7: 2260 | C7: 1800 | D7: 480 | E7: 350 | J7: 760 | N7: 860 | O7: 585 | R7: 340 | T7: 450 | U7: 320 | V7: 150 | W7: 1180 | AC7: 920 | AE7: 400 | AF7: 70 | AG7: 120 | AI7: 460 | AL7: 350 | AU7: 480 | AV7: 560 | AY7: 340 | BB7: 920 | BC7: 1260 | BD7: 1340
A8: Tundra | B8: 3820 | C8: 1760 | D8: 1280 | E8: 740 | H8: 400 | I8: 400 | J8: 760 | K8: 980 | N8: 780 | O8: 540 | R8: 480 | T8: 450 | U8: 320 | V8: 200 | W8: 2100 | AB8: 3800 | AC8: 1450 | AE8: 700 | AF8: 160 | AG8: 340 | AI8: 850 | AP8: 260 | BT8: 680
A9: Landcruiser | B9: 4800 | C9: 2850 | D9: 1280 | E9: 740 | H9: 400 | I9: 1260 | J9: 950 | K9: 1380 | N9: 750 | O9: 540 | R9: 480 | T9: 640 | U9: 450 | V9: 200 | W9: 1320 | AC9: 1450 | AE9: 700 | AF9: 160 | AG9: 340 | AH9: 180 | AI9: 1120 | AJ9: 3200 | AK9: 240 | AL9: 280
A10: 4Runner | B10: 3820 | C10: 2360 | D10: 880 | E10: 580 | J10: 760 | K10: 980 | N10: 750 | O10: 540 | R10: 480 | T10: 450 | U10: 320 | V10: 200 | W10: 1320 | AC10: 1450 | AE10: 500 | AF10: 110 | AG10: 220 | AI10: 850 | AK10: 240
A11: Prado | B11: 4680 | C11: 2820 | D11: 1280 | E11: 740 | J11: 980 | K11: 1350 | O11: 540 | R11: 1200 | T11: 680 | U11: 320 | V11: 200 | W11: 1320 | AC11: 1450 | AE11: 700 | AF11: 160 | AG11: 340 | AH11: 180 | AI11: 850 | AK11: 240 | AL11: 450 | AN11: 5800 | AP11: 640 | AS11: 15000 | AU11: 460 | AV11: 580 | AY11: 420 | BB11: 1130 | BC11: 1280 | BD11: 1640 | BU11: 2800
A12: FG Cruiser | BP12: 2050 | BR12: 1550
A13: Rav 4 | B13: 3680 | C13: 1850 | D13: 620 | E13: 520 | J13: 980 | N13: 750 | O13: 490 | Q13: 1850 | R13: 300 | S13: 200 | T13: 680 | U13: 250 | V13: 200 | W13: 780 | X13: 1230 | AC13: 650 | AD13: 680 | AE13: 600 | AF13: 90 | AG13: 280 | AI13: 750 | AX13: 330 | BD13: 1200 | BI13: 950 | CG13: 680
A14: Matrix | B14: 1850 | J14: 750 | O14: 650 | R14: 300 | T14: 380 | V14: 200 | W14: 240 | AE14: 600 | AF14: 140 | AG14: 220 | AI14: 350 | BQ14: 960 | CC14: 260
B15: 2260 | C15: 2140 | D15: 880 | E15: 580 | H15: 1380 | J15: 760 | K15: 550 | N15: 965 | O15: 585 | R15: 340 | T15: 680 | U15: 320 | V15: 150 | W15: 1180 | AC15: 920 | AE15: 700 | AF15: 160 | AG15: 340 | AH15: 180 | AI15: 460 | AK15: 260 | AL15: 350 | AU15: 480 | AV15: 560 | AY15: 340 | BB15: 920 | BC15: 1260 | BD15: 1340 | BO15: 2280
A16: Tacoma | B16: 4280 | D16: 880 | E16: 580 | H16: 400 | J16: 950 | K16: 1380 | N16: 620 | T16: 680 | V16: 300 | AE16: 600 | AF16: 100 | AG16: 180 | AH16: 180 | AP16: 300 | AY16: 680
A17: Highlander | B17: 3820 | C17: 2160 | D17: 1160 | E17: 680 | K17: 980 | N17: 965 | O17: 585 | Q17: 890 | R17: 350 | T17: 650 | U17: 420 | V17: 300 | W17: 1120 for 1 | Y17: 1360 | Z17: 550 | AC17: 920 | AE17: 500 | AF17: 110 | AG17: 280 | AI17: 1200 | AJ17: 1150 | AL17: 350 | AP17: 85 | AU17: 480 | AV17: 560 | AX17: 580 | AY17: 340 | BB17: 920 | BC17: 1260 | BD17: 1340 | BG17: 1280 | BQ17: 2850 | BR17: 1850 | BU17: 1850
A18: 4Runner | Q18: 4800 | AE18: 700 | AF18: 160 | AG18: 340 | AP18: 320
A19: Sequoia | B19: 3820 | C19: 2360 | D19: 880 | E19: 580 | J19: 760 | K19: 980 | N19: 750 | O19: 540 | R19: 480 | T19: 450 | V19: 200 | W19: 1320 | AC19: 1220 | AE19: 700 | AF19: 160 | AG19: 340 | AI19: 350 | AK19: 220 | AP19: 50
A20: Toyota Hiace | D20: 880 | W20: 1400 | AE20: 300 | AF20: 70 | AG20: 150 | AK20: 120 | AP20: 200
A21: Fortuner | B21: 3820 | C21: 2140 | D21: 880 | E21: 580 | J21: 760 | O21: 585 | R21: 340 | T21: 650 | U21: 420 | V21: 250 | W21: 1180 | AC21: 920 | AE21: 700 | AF21: 110 | AG21: 220 | AI21: 750 | AK21: 220 | AL21: 350 | AU21: 480 | AV21: 560 | AY21: 340 | BB21: 920 | BC21: 1260 | BD21: 1340
AO22: 300
A23: NISSAN | AO23: 85
A24: Sentra | B24: =B3 -> 2850 | C24: =C3 -> 1820 | D24: 350 | E24: =E3 -> 580 | J24: 520 | O24: =O3 -> 480 | R24: =R3 -> 560 | S24: =S3 -> 300 | T24: =T3 -> 520 | V24: =V3 -> 200 | W24: =W3 -> 800 | Y24: =Y3 -> 1360 | AC24: =AC3 -> 455.84 | AE24: =AE3 -> 600 | AF24: =AF3 -> 140 | AG24: 100 | AI24: =AI3 -> 450 | AL24: =AL3 -> 350 | AO24: 180 | AR24: =AR3 -> 180 | BN24: 480
A25: Almera | D25: 380 | E25: 350 | AE25: 250 | AF25: 60 | AG25: 120 | AI25: 280 | AO25: 320
A26: Versa | B26: 2860 | C26: 2180 | D26: 380 | E26: 350 | R26: 480 | S26: 260 | T26: 480 | U26: 320 | V26: 200 | AE26: 250 | AF26: 60 | AG26: 120 | AL26: 350 | AO26: 580 | AS26: 480 | AX26: 320
A27: Micra | AE27: 250 | AS27: 560 | BE27: 460
A28: Sunny | AE28: 250 | AS28: 400 | BE28: 350
A29: Altima | D29: 380 | E29: 320 | Y29: =70*4 -> 280 | AE29: 250 | AF29: 70 | AG29: 120 | AS29: 50 | BE29: 200
A30: Skyline | AE30: 200 | AS30: 300 | BE30: 200
A31: Maxima | AE31: 250 | AS31: 250
A32: March | AE32: 250
A33: Rogue | B33: 2180 | C33: 1460 | D33: 480 | E33: 360 | J33: 880 | N33: 750 | O33: 490 | Q33: 890 | R33: 300 | S33: 200 | T33: 480 | U33: 250 | V33: 200 | W33: 780 | X33: 1230 | AC33: 650 | AD33: 680 | AE33: 400 | AF33: 80 | AG33: 16 | AI33: 280 | AX33: 330 | BD33: 1200 | BI33: 950 | CG33: 680
A34: Juke | D34: 380 | E34: 350 | AA34: =480+480 -> 960 | AE34: 400
A35: Hardbody | B35: 2485 | C35: 2260 | D35: 380 | E35: 350 | J35: 440 | K35: 580 | T35: 250 | V35: 190 | AE35: 600 | AF35: 170 | AG35: 310 | AH35: 180
A36: Navara | B36: 2485 | C36: 2260 | D36: 480 | E36: 360 | J36: 440 | K36: 860 | O36: 575 | R36: 320 | T36: 420 | V36: 190 | W36: 1320 | AC36: 960 | AE36: 600 | AF36: 170 | AG36: 310 | AH36: 180 | AK36: 580 | AL36: 350 | AU36: 480 | AV36: 640 | AY36: 340 | BB36: 865 | BC36: 1280 | BD36: 1460
A37: Frontier | B37: 2485 | C37: 2260 | D37: 480 | E37: 360 | J37: 440 | K37: 860 | O37: 575 | R37: 320 | T37: 420 | V37: 190 | W37: 1320 | AC37: 960 | AE37: 600 | AF37: 170 | AG37: 310 | AH37: 180 | AK37: 580 | AL37: 350 | AU37: 480 | AV37: 640 | AY37: 340 | BB37: 865 | BC37: 1280 | BD37: 1460 | BE37: 1460
A38: Qashqia | B38: 2180 | C38: 1460 | D38: 880 | E38: 620 | J38: 880 | N38: 750 | O38: 490 | Q38: 890 | R38: 300 | S38: 200 | T38: 480 | U38: 250 | V38: 200 | W38: 780 | X38: 1230 | AC38: 650 | AD38: 680 | AE38: 600 | AF38: 125 | AG38: 240 | AH38: 180 | AI38: 1100 | AK38: 260 | AX38: 330 | BD38: 1200 | BI38: 950 | CG38: 680
A39: Pathfinder | B39: 2485 | C39: 2260 | D39: 480 | E39: 360 | J39: 440 | K39: 860 | O39: 575 | R39: 320 | T39: 420 | V39: 190 | W39: 1320 | AC39: 960 | AE39: 600 | AF39: 170 | AG39: 310 | AH39: 180 | AI39: 540 | AL39: 350 | AU39: 950 | AV39: 640 | AY39: 340 | BB39: 865 | BC39: 1280 | BD39: 1460 | BG39: 1160
A40: Murano
...

Sheet Dubai Auto Pricing
D2: HILUX | F2: LANDCRUISER | H2: PRADO
A3: ITEMS | B3: COROLLA | C3: CAMRY | D3: PETROL | E3: DIESEL | F3: PETROL | G3: DIESEL | H3: PETROL | I3: DIESEL
A4: ENGINE OIL | B4: 150 | C4: =B4 -> 150 | D4: 200 | E4: =D4 -> 200 | F4: 200 | G4: 300 | H4: =F4 -> 200 | I4: =G4 -> 300
A5: OIL FILTER | B5: 70 | C5: =B5 -> 70 | D5: 70 | E5: =D5 -> 70 | F5: 85 | G5: =F5 -> 85 | H5: =F5 -> 85 | I5: =G5 -> 85
A6: AIR FILTER | B6: 110 | C6: =B6 -> 110 | D6: 120 | E6: 210 | F6: 180 | G6: =F6 -> 180 | H6: =F6 -> 180 | I6: =G6 -> 180
A7: FUEL FILTER | B7: 0 | C7: =B7 -> 0 | D7: 0 | E7: 210 | F7: 0 | G7: 220 | H7: =F7 -> 0 | I7: =G7 -> 220
A8: FUEL CLEANER | B8: 50 | C8: =B8 -> 50 | D8: 50 | E8: 0 | F8: 50 | G8: 0 | H8: =F8 -> 50 | I8: =G8 -> 0
A9: SPARK PLUGS | B9: 350 | C9: =B9 -> 350 | D9: 460 | E9: 0 | F9: 540 | G9: 0 | H9: =F9 -> 540 | I9: =G9 -> 0
A10: BRAKE PAD - F | B10: 367 | C10: 387 | D10: 385 | E10: =D10 -> 385 | F10: 587 | G10: =F10 -> 587 | H10: =F10 -> 587 | I10: =G10 -> 587 | N10: =10%*1893 -> 189.3
A11: BRAKE PAD - R | B11: 338 | C11: 342 | D11: 346 | E11: =D11 -> 346 | F11: 366 | G11: =F11 -> 366 | H11: 360 | I11: =G11 -> 366 | N11: =1%*1893 -> 18.93
A12: FRONT SHOCK | N12: =19*2 -> 38
A13: REAR SHOCKS | N13: =1893+38 -> 1931
A14: TOP BALL JOINT | N14: =1950-1931 -> 19 | T14: 350
A15: DOWN BALL JOINT | T15: 80
A16: TIE ROD END | T16: 150
A17: STABILIZER LINK | T17: 50
A18: LOWER ARM | T18: 650
A19: UPPER ARM
A20: BALL ENDS
A21: DRIVE SHAFT
A22: LOWER ARM BUSHINGS
A23: STABILIZER BUSHINGS
A24: HOB
A25: HOB BEARING
K35: =625-335.5 -> 289.5

Sheet Servicing Schedule
O14: =2240-1440 -> 800
L15: 1220
L16: 580
L17: 300
L18: 5200
L19: 650
L20: 500 | M20: 1400
L21: -2400 | M21: 680
M22: 760
M23: 420 | T23: 200
M24: 380 | T24: 80
M25: 260 | T25: 140
P26: =200*13 -> 2600 | T26: 220
P27: =12*50 -> 600 | T27: 380
P28: 8500 | T28: 350
P29: 1520 | T29: 200
P40: =SUM(P26:P39) -> 13220
M52: 680
M53: 1510
M54: 320
M55: 320
M56: 250
M57: 200
M58: 780
M59: 500
M68: =SUM(M52:M67) -> 4560

Sheet Auctus Pricing
Q6: 200
Q7: 80
B8: BASIC PRICING SCHEDULES FOR THE MOVING TOYOTA BRANDS & ITEMS | Q8: 140
M9: =16*20 -> 320 | Q9: 220
D10: HILUX | F10: LANDCRUISER | H10: PRADO | M10: 450 | Q10: 100
A11: ITEMS | B11: COROLLA | C11: CAMRY | D11: PETROL | E11: DIESEL | F11: PETROL | G11: DIESEL | H11: PETROL | I11: DIESEL | M11: 10
A12: ENGINE OIL | B12: 200 | C12: =B12 -> 200 | D12: 200 | E12: =D12 -> 200 | F12: 300 | G12: 300 | H12: =F12 -> 300 | I12: =G12 -> 300
A13: OIL FILTER | B13: 70 | C13: =B13 -> 70 | D13: 70 | E13: =D13 -> 70 | F13: 85 | G13: =F13 -> 85 | H13: =F13 -> 85 | I13: =G13 -> 85
A14: AIR FILTER | B14: 110 | C14: =B14 -> 110 | D14: 120 | E14: 210 | F14: 180 | G14: =F14 -> 180 | H14: =F14 -> 180 | I14: =G14 -> 180 | M14: =SUM(M9:M13) -> 780
A15: FUEL FILTER | B15: 0 | C15: =B15 -> 0 | D15: 0 | E15: 210 | F15: 0 | G15: 220 | H15: =F15 -> 0 | I15: =G15 -> 220
A16: FUEL CLEANER | B16: 50 | C16: =B16 -> 50 | D16: 50 | E16: 0 | F16: 50 | G16: 0 | H16: =F16 -> 50 | I16: =G16 -> 0
A17: SPARK PLUGS | B17: 350 | C17: =B17 -> 350 | D17: 460 | E17: 0 | F17: 540 | G17: 0 | H17: =F17 -> 540 | I17: =G17 -> 0 | Q17: 200
A18: BRAKE PAD - F | B18: 367 | C18: 387 | D18: 385 | E18: =D18 -> 385 | F18: 587 | G18: =F18 -> 587 | H18: =F18 -> 587 | I18: =G18 -> 587 | Q18: 120
A19: BRAKE PAD - R | B19: 338 | C19: 342 | D19: 346 | E19: =D19 -> 346 | F19: 366 | G19: =F19 -> 366 | H19: =F19 -> 366 | I19: =G19 -> 366 | Q19: 70
A20: FRONT SHOCK | B20: ='Main Pricing'!B3 -> 2850 | C20: ='Main Pricing'!B5 -> 2350 | D20: ='Main Pricing'!B15 -> 2260 | E20: =D20 -> 2260 | F20: ='Main Pricing'!B9 -> 4800 | G20: =F20 -> 4800 | H20: =F20 -> 4800 | I20: =G20 -> 4800 | Q20: 50
A21: REAR SHOCKS | B21: ='Main Pricing'!C3 -> 1820 | C21: ='Main Pricing'!C5 -> 1820 | D21: ='Main Pricing'!C15 -> 2140 | E21: =D21 -> 2140 | F21: ='Main Pricing'!C9 -> 2850 | G21: =F21 -> 2850 | H21: =F21 -> 2850 | I21: =H21 -> 2850 | M21: 200 | Q21: 350
A22: TOP BALL JOINT | B22: 340 | C22: 360 | D22: 365 | E22: =D22 -> 365 | F22: 980 | G22: =F22 -> 980 | H22: =F22 -> 980 | I22: =H22 -> 980 | M22: 70 | Q22: 100
A23: DOWN BALL JOINT | B23: 420 | C23: 450 | D23: 510 | E23: =D23 -> 510 | F23: 760 | G23: =F23 -> 760 | H23: =F23 -> 760 | I23: =H23 -> 760 | M23: 110 | Q23: =SUM(Q17:Q22) -> 890
A24: TIE ROD END | B24: ='Main Pricing'!O3 -> 480 | C24: 480 | D24: 485 | E24: =D24 -> 485 | F24: ='Main Pricing'!O9 -> 540 | G24: =F24 -> 540 | H24: =F24 -> 540 | I24: =H24 -> 540 | K24: 350 | M24: 50
A25: STABILIZER LINK | B25: ='Main Pricing'!T3 -> 520 | C25: 350 | D25: 390 | E25: =D25 -> 390 | F25: ='Main Pricing'!T9 -> 640 | G25: =F25 -> 640 | H25: =F25 -> 640 | I25: =H25 -> 640 | K25: 320 | M25: 100
A26: BALL ENDS | B26: 320 | C26: 350 | D26: 405 | E26: =D26 -> 405 | F26: ='Main Pricing'!N9 -> 750 | G26: =F26 -> 750 | H26: =F26 -> 750 | I26: =H26 -> 750 | K26: 200 | O26: 300
A27: LOWER ARM BUSHINGS | B27: 280 | C27: 280 | D27: 280 | E27: =D27 -> 280 | F27: ='Main Pricing'!R9 -> 480 | G27: =F27 -> 480 | H27: =F27 -> 480 | I27: =H27 -> 480 | K27: 250 | O27: 85
A28: STABILIZER BUSHINGS | B28: 210 | C28: 210 | D28: 220 | E28: =D28 -> 220 | F28: 220 | G28: =F28 -> 220 | H28: =F28 -> 220 | I28: =H28 -> 220 | K28: 150 | O28: 180
K29: 480 | O29: 50
K30: 300 | O30: 2820
A31: NB: Labour / Workmanship charges is dependendent on scope of work | O31: 760
A32: Again, all prices are VAT/NHIL exclusive | O32: 980
O33: 540
O34: 200
K35: 950 | O35: 580
K36: 140 | O36: 500
K37: 210
K38: 580 | M38: 200
K39: 180 | M39: 70
K40: 200 | M40: 110
K41: 40 | M41: 50
K42: 110 | M42: 100
K43: 50
K44: 950
K45: 640
...

Sheet Engine Works
B1: Injec. | C1: Spark P | D1: Crnk S | E1: ABS S | F1: Ang S | G1: Coil S | H1: Oxy S | I1: Cam SS | J1: Fuel Pump | K1: Start. | L1: Altn
A2: TOYOTA
A3: Corolla | B3: 400 | C3: 280 | D3: 450 | E3: 350 | F3: 750 | G3: 250 | H3: 550 | I3: 450 | J3: 550 | K3: 450 | R3: 300
A4: Camry | B4: =B3 -> 400 | C4: =C3 -> 280 | D4: 450 | E4: =E3 -> 350 | F4: =F3 -> 750 | G4: =G3 -> 250 | H4: =H3 -> 550 | I4: =I3 -> 450 | J4: =J3 -> 550 | K4: 450 | R4: 100
A5: Avensis | B5: =B4 -> 400 | C5: 320 | D5: 450 | E5: =E4 -> 350 | F5: =F4 -> 750 | G5: =G4 -> 250 | H5: =H4 -> 550 | I5: =I4 -> 450 | J5: =J4 -> 550 | K5: 450 | R5: 329
A6: Venza | B6: =B5 -> 400 | C6: =C5 -> 320 | D6: 450 | E6: =E5 -> 350 | F6: =F5 -> 750 | G6: =G5 -> 250 | H6: =H5 -> 550 | I6: =I5 -> 450 | J6: =J5 -> 550 | K6: 500 | O6: 200 | R6: 50
A7: Tundra | B7: 600 | C7: =80*6 -> 480 | D7: 550 | E7: =E6 -> 350 | F7: =F6 -> 750 | G7: =G6 -> 250 | H7: =H6 -> 550 | I7: =I6 -> 450 | J7: 650 | K7: 550 | O7: 80 | R7: 100
A8: Landcruiser | B8: 600 | C8: =C7 -> 480 | D8: 650 | E8: =E7 -> 350 | F8: =F7 -> 750 | G8: =G7 -> 250 | H8: =H7 -> 550 | I8: =I7 -> 450 | J8: 750 | K8: 550 | O8: 150
A9: Rav 4 | B9: 400 | C9: 320 | D9: 450 | E9: =E8 -> 350 | F9: =F8 -> 750 | G9: =G8 -> 250 | H9: =H8 -> 550 | I9: =I8 -> 450 | J9: =J7 -> 650 | K9: 550 | O9: 350 | T9: 2200
A10: Matrix | B10: 400 | C10: 320 | D10: 450 | E10: =E9 -> 350 | F10: =F9 -> 750 | G10: =G9 -> 250 | H10: =H9 -> 550 | I10: =I9 -> 450 | J10: =J9 -> 650 | K10: 550 | O10: 380 | T10: 680
A11: Hilux | B11: 400 | C11: 320 | D11: 450 | E11: =E10 -> 350 | F11: =F10 -> 750 | G11: =G10 -> 250 | H11: =H10 -> 550 | I11: =I10 -> 450 | J11: =J10 -> 650 | K11: 550 | O11: 320 | T11: 300
A12: Highlander | B12: =B10 -> 400 | C12: 320 | D12: 550 | E12: =E11 -> 350 | F12: =F11 -> 750 | G12: =G11 -> 250 | H12: =H11 -> 550 | I12: =I11 -> 450 | J12: =J11 -> 650 | K12: 550 | O12: 50 | W12: 450
A13: 4Runner | B13: =B8 -> 600 | C13: 480 | D13: 650 | E13: =E12 -> 350 | F13: =F12 -> 750 | G13: =G12 -> 250 | H13: =H12 -> 550 | I13: =I12 -> 450 | J13: =J8 -> 750 | K13: 550 | O13: 200 | W13: 380
A14: Sequoia | B14: =B13 -> 600 | C14: 480 | D14: 650 | E14: =E13 -> 350 | F14: =F13 -> 750 | G14: =G13 -> 250 | H14: =H13 -> 550 | I14: =I13 -> 450 | J14: =J13 -> 750 | K14: 550 | W14: 350
A15: Takoma | B15: =B11 -> 400 | C15: 320 | D15: 550 | E15: =E14 -> 350 | F15: =F14 -> 750 | G15: =G14 -> 250 | H15: =H14 -> 550 | I15: =I14 -> 450 | J15: =J11 -> 650 | K15: 550 | W15: 320
A16: Fortuner | B16: =B12 -> 400 | C16: 320 | D16: 550 | E16: =E15 -> 350 | F16: =F15 -> 750 | G16: =G15 -> 250 | H16: =H15 -> 550 | I16: =I15 -> 450 | J16: =J15 -> 650 | K16: 550 | O16: =SUM(O6:O15) -> 1730 | W16: 200
M17: 350 | W17: 200
A18: NISSAN | M18: 1565 | W18: 300
A19: Sentra | B19: =B3 -> 400
A20: Almera | B20: =B19 -> 400 | R20: 200
A21: Versa | B21: =B20 -> 400 | R21: 650
A22: Micra | B22: =B21 -> 400 | R22: 280 | U22: 200
A23: Sunny | B23: =B22 -> 400 | O23: 200 | R23: 350 | U23: 120
A24: Altima | B24: =B23 -> 400 | O24: 40 | R24: 150 | U24: 70
A25: Skyline | B25: =B24 -> 400 | O25: 120 | R25: 300 | U25: 50
A26: Maxima | B26: =B25 -> 400 | O26: 50 | U26: 100 | W26: =SUM(W12:W25) -> 2200
A27: March | B27: =B26 -> 400 | O27: 100 | U27: =SUM(U22:U26) -> 540
A28: Rogue | B28: =B27 -> 400
A29: Juke | B29: =B28 -> 400 | R29: =SUM(R20:R28) -> 1930
A30: Hardbody | B30: =B29 -> 400 | P30: 200
A31: Navarra | B31: =B30 -> 400
A32: Frontier | B32: 600
A33: Pathfinder | B33: 600 | S33: 100 | V33: 1600
A34: NISSAN | B34: Injec. | C34: Spark P | D34: Crnk S | E34: ABS S | F34: Ang S | G34: Coil S | H34: Oxy S | I34: Cam SS | J34: Fuel Pump | K34: Start. | L34: Altn | M34: SB | S34: 780 | V34: 750
A35: Xterra | B35: 400 | S35: 380 | V35: 200
A36: Xtrail | S36: 250
A37: Murrano | Q37: 300 | S37: 140
A38: Patrol | O38: 580 | Q38: 85 | S38: 140
A39: Armada | O39: 350 | Q39: 180 | S39: 480
O40: 750 | Q40: 50 | S40: 500
...

Sheet Sheet1
D3: Shock Absorber - F | E3: 1800
D4: Shock Absorber - R | E4: 1200 | G4: =250+150+1440+480+380+200+1200+1680+2170+600 -> 8550 | I4: 4000 | J4: 600 | K4: 300 | M4: ]\]\ | O4: 270+50 | Y4: 660
D5: Brake Pad - F | E5: 380 | I5: 350 | M5: 850 | Y5: 250
D6: Brake Pad - R | E6: 350 | H6: 2820 | I6: 70 | M6: 260 | P6: 200 | R6: 650 | V6: 580 | Y6: 580
B7: 2650 | D7: Engine Oil | E7: 280 | H7: 760 | I7: 300 | M7: 200 | V7: 450 | Y7: 480
B8: 2800 | D8: Oil Filter | E8: 80 | G8: 300 | H8: 980 | I8: 40 | L8: 300 | V8: 1280 | Y8: 1070
B9: 750 | D9: Air Filter | E9: 120 | G9: 85 | H9: 450 | I9: 1000 | J9: 300 | L9: 85 | V9: 4820 | Y9: 390
B10: 300 | D10: Fuel Cleaner | E10: 50 | G10: 180 | H10: 200 | J10: 85 | L10: 180 | M10: =SUM(M4:M9) -> 1310 | V10: 400 | X10: 1980 | Y10: 240
B11: 620 | D11: Spark Plugs - V6 | E11: 570 | G11: 220 | H11: 580 | J11: 180 | L11: 220 | T11: 510 | X11: 1260 | Y11: 120
B12: 400 | D12: Spark Plugs - V6 | E12: 720 | G12: 100 | H12: 350 | J12: 50 | L12: 100 | T12: 210 | X12: 440 | Y12: 330
I13: =SUM(I4:I12) -> 5760 | J13: 100 | T13: 320 | X13: 580 | Y13: 2260
B14: =SUM(B7:B13) -> 7520 | D14: Labour for Oil Change | E14: 50 | G14: =SUM(G8:G13) -> 885 | Q14: 2485 | T14: 200 | X14: 250 | Y14: 550
D15: Labour for Brakes only | E15: 100 | O15: 300 | Q15: 2260 | V15: 1380 | X15: 200 | Y15: 120 | AC15: 250
D16: Labour for Shocks | E16: 500 | O16: 85 | Q16: 1850 | V16: 950 | X16: 400 | Y16: 730 | AC16: 70
H17: =SUM(H6:H16) -> 6140 | O17: 180 | Q17: 400 | V17: 200 | Y17: 200 | AC17: 140
D18: Medicals - 3 days | O18: 50 | V18: 200 | Y18: 1260 | AC18: 50
E19: Lab - Fee | F19: Prof. Chrgs | G19: Dispatch | I19: =SUM(I8:I18) -> 6800 | L19: GHc | M19: Eur | O19: 580 | T19: 200 | V19: 200 | Y19: 700 | AC19: 350
B20: 200 | D20: In-House | E20: 200 | F20: 500 | G20: 0 | H20: =SUM(E20:G20) -> 700 | K20: Visa Processing | M20: 60 | O20: 350 | Q20: =SUM(Q14:Q19) -> 6995 | T20: 70 | Y20: 9 | AC20: 380
B21: 85 | D21: Off-site | E21: 200 | F21: 500 | G21: 300 | H21: =SUM(E21:G21) -> 1000 | K21: Visa Fee | M21: 20 | O21: 200 | T21: 160 | Y21: 350 | AC21: 200
B22: 220 | K22: Courrier | M22: 140 | N22: =M22/0.82 -> 170.73171 | T22: 220 | Y22: 150
B23: 120 | K23: Medicals | L23: 1000 | N23: =L23/4.46 -> 224.21525 | T23: 200 | Y23: 250
B24: 380 | K24: Police Clearance | L24: 1500 | N24: =L24/4.46 -> 336.32287 | T24: 380 | Y24: 670
B25: 200 | D25: Police Clearance - 7 days | K25: Miscellaneous | L25: 400 | N25: =L25/4.46 -> 89.686099 | S25: 1500 | V25: 850 | Y25: 500 | AC25: =SUM(AC15:AC24) -> 1440
D26: Docs Needed | F26: Charges | G26: Facilitation | L26: =SUM(L20:L25) -> 2900 | M26: =SUM(M20:M25) -> 220 | N26: =SUM(N20:N25) -> 820.95592 | S26: 350 | V26: 400 | Y26: 200
D27: Biopage of Passport | E27: 1 | F27: 1200 | G27: 300 | H27: =F27+G27 -> 1500 | S27: 300 | V27: 1240 | Y27: 660
D28: Passport Pictures | E28: 2 | V28: 300 | X28: 300 | Y28: 330
D29: Schools attended in Gh | E29: 1 | P29: 300 | V29: 110 | X29: 110 | Y29: 100
D30: Parents Name | P30: 110 | T30: 850 | V30: 480 | X30: 480 | Y30: 370
D31: Oversea Address | P31: 480 | T31: 400 | V31: 50 | X31: 50 | Y31: 650
P32: 50 | T32: 1240 | V32: 400 | X32: 100 | Y32: 870
P33: 100 | Y33: 350
B34: 650 | J34: 420 | Y34: 970
B35: 200 | J35: 450 | L35: 1980 | N35: 300 | R35: 380 | T35: 400 | Y35: 310
B36: 350 | I36: 400 | J36: 300 | L36: 460 | N36: 80 | R36: 350 | Y36: 570
B37: 160 | I37: 100 | J37: 80 | L37: 300 | N37: 140 | R37: 320 | V37: =SUM(V24:V36) -> 3830 | Y37: 800
B38: 200 | I38: 320 | J38: 140 | N38: 50 | R38: 200 | T38: =SUM(T30:T37) -> 2890 | Y38: 600
B39: 380 | I39: 50 | J39: 50 | N39: 100 | Y39: 510
B40: 480 | I40: 150 | J40: 200 | Y40: 430
B41: 300 | G41: 2720 | Y41: 250
G42: 1100 | Y42: 490
...
